Workbook

Sheet Optimization_Notes
A1: Refinery Production Planning – Optimization Notes (Objective Function & Constraints)
A2: Multi-period LP: 31 days (Oct 2026), 4 crudes, CDU → Reformer / RFCC / DHT, 10 tanks. Days 1–11 actual (locked), days 12–31 to optimise.
A5: 1. PURPOSE & WORKFLOW
A6: This workbook is a test-bed for a Python optimizer. Excel holds the data, the current (manual) plan and all checks; Python reads the data, solves for the best plan, and writes the decision variables back into Daily_Plan. Excel then recalculates margins, tank balances and constraint checks so the optimizer result can be verified independently of the solver.
A7: Step 1 | B7: Read parameters: Crude_Data, Unit_Data, Product_Data, Tank_Master, Crude_Receipts, Product_Liftings.
A8: Step 2 | B8: Read Daily_Plan rows 5–35. Rows with Status = 'Actual' are fixed history; rows with Status = 'Plan' are free.
A9: Step 3 | B9: Build and solve the LP below (scipy.optimize.linprog / HiGHS, PuLP or Pyomo all work).
A10: Step 4 | B10: Write optimal x, r, f into Daily_Plan!D:I for Plan rows only (green cells).
A11: Step 5 | B11: Open in Excel → check Constraint_Check!X37 = 0 and compare Daily_Plan KPI 'Plan-days margin' against the benchmark in section 9.
A13: 2. COLOUR LEGEND
B14: Blue text, yellow fill | C14: Parameter / input – edit to run scenarios
B15: Blue text, green fill | C15: Decision variable – optimizer writes here (Daily_Plan Plan rows)
B16: Blue text, grey fill | C16: Actual (locked) day – do not optimise
B17: Black text | C17: Formula / calculation
B18: Green text | C18: Link to another worksheet
A20: 3. SETS & INDICES
B21: Symbol | C21: Meaning | D21: Members / Excel source
B22: t ∈ T | C22: Day of horizon | D22: 1…31 (Daily_Plan col A). T_plan = days with Status 'Plan' (12…31)
B23: c ∈ C | C23: Crude grade | D23: Arab Light, Murban, Tapis, Kimanis (Crude_Data C3:F3)
B24: p ∈ P | C24: Finished product | D24: LPG, Naphtha, Gasoline 95, Jet A-1, Diesel B10, Fuel Oil (Product_Data C3:H3)
B25: k ∈ K | C25: Tank | D25: 4 crude tanks + 6 product tanks (Tank_Master A4:A13)
A27: 4. DECISION VARIABLES (per plan day t, units kbbl/d)
B28: Variable | C28: Meaning | D28: Excel location | E28: Bounds
B29: x[c,t] | C29: Crude c charged to the CDU | D29: Daily_Plan!D:G | E29: 0 … Xmax_c
B30: r[t] | C30: SR naphtha routed to the Reformer (rest sold as Naphtha) | D30: Daily_Plan!H | E30: Rmin … Rmax
B31: f[t] | C31: Atmospheric residue routed to the RFCC (rest goes to Fuel Oil) | D31: Daily_Plan!I | E31: Fmin … Fmax
B32: I[k,t] | C32: Closing inventory of tank k (state variable, can be eliminated by substitution) | D32: Tank_Balance!I | E32: Min heel … Capacity
A33: Total: 6 free variables × 20 plan days = 120 decision variables (+ 200 inventory states if modelled explicitly).
A35: 5. DERIVED FLOWS (all linear in x, r, f – see Daily_Plan formulas)
B36: Quantity | C36: Expression | D36: Excel column
B37: CDU_t | C37: Σc x[c,t] | D37: Daily_Plan!J
B38: Cut_j,t (j = LPG, Naph, Kero, GO, AR) | C38: Σc y[c,j] · x[c,t] | D38: Daily_Plan!K:O
B39: DHT_t | C39: GO_t + yLCO · f[t] | D39: Daily_Plan!W
B40: LPG_t | C40: LPG_SR,t + yRef,LPG · r[t] + yFCC,LPG · f[t] | D40: Daily_Plan!X
B41: Naphtha_t | C41: Naph_t − r[t] | D41: Daily_Plan!Y
B42: Gasoline_t | C42: yRef,Reformate · r[t] + yFCC,Gasoline · f[t] | D42: Daily_Plan!Z
B43: Jet_t | C43: Kero_t | D43: Daily_Plan!AA
B44: Diesel_t | C44: yDHT · DHT_t | D44: Daily_Plan!AB
B45: FuelOil_t | C45: AR_t − f[t] + ySlurry · f[t] | D45: Daily_Plan!AC
A47: 6. OBJECTIVE FUNCTION – maximise gross margin over plan days ($k)
...

Sheet Daily_Plan
A1: Refinery Daily Production Plan – October 2026 (kbbl/d, $k/d)
A2: Days 1–11 = ACTUAL (locked). Days 12–31 = PLAN. Green cells = decision variables the Python optimizer writes back; everything else is calculated.
D3: DECISION VARIABLES (kbbl/d) | J3: CDU – straight-run cuts | Q3: Reformer | S3: RFCC | W3: DHT | X3: Product make (kbbl/d) | AD3: Quality | AE3: Economics ($k/d)
A4: Day | B4: Date | C4: Status | D4: Crude: Arab Light | E4: Crude: Murban | F4: Crude: Tapis | G4: Crude: Kimanis | H4: Reformer feed | I4: RFCC feed | J4: CDU total | K4: SR LPG | L4: SR Naphtha | M4: SR Kerosene | N4: SR Gasoil | O4: Atm Residue | P4: Residue S (wt%) | Q4: Reformate | R4: Reformer LPG | S4: FCC gasoline | T4: FCC LPG | U4: LCO | V4: Slurry | W4: DHT feed | X4: LPG | Y4: Naphtha | Z4: Gasoline 95 | AA4: Jet A-1 | AB4: Diesel B10 | AC4: Fuel Oil | AD4: Gasoline RON | AE4: Product revenue | AF4: Crude cost | AG4: Opex | AH4: Gross margin | AI4: Margin $/bbl crude
A5: 1 | B5: 46296 | C5: Actual | D5: 40 | E5: 40 | F5: 40 | G5: 30 | H5: 22 | I5: 32 | J5: =SUM(D5:G5) -> 150 | K5: =SUMPRODUCT($D5:$G5,Crude_Data!$C$5:$F$5) -> 3.8 | L5: =SUMPRODUCT($D5:$G5,Crude_Data!$C$6:$F$6) -> 31.6 | M5: =SUMPRODUCT($D5:$G5,Crude_Data!$C$7:$F$7) -> 23.3 | N5: =SUMPRODUCT($D5:$G5,Crude_Data!$C$8:$F$8) -> 38.4 | O5: =SUMPRODUCT($D5:$G5,Crude_Data!$C$9:$F$9) -> 51.4 | P5: =IF(O5>0,SUMPRODUCT($D5:$G5,Crude_Data!$C$9:$F$9,Crude_Data!$C$12:$F$12)/O5,0) -> 1.4610895 | Q5: =H5*Unit_Data!$D$11 -> 18.48 | R5: =H5*Unit_Data!$D$12 -> 1.76 | S5: =I5*Unit_Data!$D$17 -> 16.64 | T5: =I5*Unit_Data!$D$18 -> 5.76 | U5: =I5*Unit_Data!$D$19 -> 5.76 | V5: =I5*Unit_Data!$D$20 -> 1.92 | W5: =N5+U5 -> 44.16 | X5: =K5+R5+T5 -> 11.32 | Y5: =L5-H5 -> 9.6 | Z5: =Q5+S5 -> 35.12 | AA5: =M5 -> 23.3 | AB5: =W5*Unit_Data!$D$25 -> 43.2768 | AC5: =O5-I5+V5 -> 21.32 | AD5: =IF(Z5>0,(Q5*Unit_Data!$D$26+S5*Unit_Data!$D$27)/Z5,0) -> 95.157175 | AE5: =SUMPRODUCT(X5:AC5,Product_Data!$C$4:$H$4) -> 13345.484 | AF5: =SUMPRODUCT(D5:G5,Crude_Data!$C$4:$F$4) -> 12095 | AG5: =J5*Unit_Data!$D$7+H5*Unit_Data!$D$10+I5*Unit_Data!$D$16+W5*Unit_Data!$D$24 -> 399.24 | AH5: =AE5-AF5-AG5 -> 851.244 | AI5: =IF(J5>0,AH5/J5,0) -> 5.67496
A6: 2 | B6: 46297 | C6: Actual | D6: 40 | E6: 40 | F6: 40 | G6: 30 | H6: 22 | I6: 32 | J6: =SUM(D6:G6) -> 150 | K6: =SUMPRODUCT($D6:$G6,Crude_Data!$C$5:$F$5) -> 3.8 | L6: =SUMPRODUCT($D6:$G6,Crude_Data!$C$6:$F$6) -> 31.6 | M6: =SUMPRODUCT($D6:$G6,Crude_Data!$C$7:$F$7) -> 23.3 | N6: =SUMPRODUCT($D6:$G6,Crude_Data!$C$8:$F$8) -> 38.4 | O6: =SUMPRODUCT($D6:$G6,Crude_Data!$C$9:$F$9) -> 51.4 | P6: =IF(O6>0,SUMPRODUCT($D6:$G6,Crude_Data!$C$9:$F$9,Crude_Data!$C$12:$F$12)/O6,0) -> 1.4610895 | Q6: =H6*Unit_Data!$D$11 -> 18.48 | R6: =H6*Unit_Data!$D$12 -> 1.76 | S6: =I6*Unit_Data!$D$17 -> 16.64 | T6: =I6*Unit_Data!$D$18 -> 5.76 | U6: =I6*Unit_Data!$D$19 -> 5.76 | V6: =I6*Unit_Data!$D$20 -> 1.92 | W6: =N6+U6 -> 44.16 | X6: =K6+R6+T6 -> 11.32 | Y6: =L6-H6 -> 9.6 | Z6: =Q6+S6 -> 35.12 | AA6: =M6 -> 23.3 | AB6: =W6*Unit_Data!$D$25 -> 43.2768 | AC6: =O6-I6+V6 -> 21.32 | AD6: =IF(Z6>0,(Q6*Unit_Data!$D$26+S6*Unit_Data!$D$27)/Z6,0) -> 95.157175 | AE6: =SUMPRODUCT(X6:AC6,Product_Data!$C$4:$H$4) -> 13345.484 | AF6: =SUMPRODUCT(D6:G6,Crude_Data!$C$4:$F$4) -> 12095 | AG6: =J6*Unit_Data!$D$7+H6*Unit_Data!$D$10+I6*Unit_Data!$D$16+W6*Unit_Data!$D$24 -> 399.24 | AH6: =AE6-AF6-AG6 -> 851.244 | AI6: =IF(J6>0,AH6/J6,0) -> 5.67496
A7: 3 | B7: 46298 | C7: Actual | D7: 41 | E7: 38 | F7: 41 | G7: 30 | H7: 23 | I7: 33 | J7: =SUM(D7:G7) -> 150 | K7: =SUMPRODUCT($D7:$G7,Crude_Data!$C$5:$F$5) -> 3.79 | L7: =SUMPRODUCT($D7:$G7,Crude_Data!$C$6:$F$6) -> 31.52 | M7: =SUMPRODUCT($D7:$G7,Crude_Data!$C$7:$F$7) -> 23.29 | N7: =SUMPRODUCT($D7:$G7,Crude_Data!$C$8:$F$8) -> 38.46 | O7: =SUMPRODUCT($D7:$G7,Crude_Data!$C$9:$F$9) -> 51.44 | P7: =IF(O7>0,SUMPRODUCT($D7:$G7,Crude_Data!$C$9:$F$9,Crude_Data!$C$12:$F$12)/O7,0) -> 1.4697998 | Q7: =H7*Unit_Data!$D$11 -> 19.32 | R7: =H7*Unit_Data!$D$12 -> 1.84 | S7: =I7*Unit_Data!$D$17 -> 17.16 | T7: =I7*Unit_Data!$D$18 -> 5.94 | U7: =I7*Unit_Data!$D$19 -> 5.94 | V7: =I7*Unit_Data!$D$20 -> 1.98 | W7: =N7+U7 -> 44.4 | X7: =K7+R7+T7 -> 11.57 | Y7: =L7-H7 -> 8.52 | Z7: =Q7+S7 -> 36.48 | AA7: =M7 -> 23.29 | AB7: =W7*Unit_Data!$D$25 -> 43.512 | AC7: =O7-I7+V7 -> 20.42 | AD7: =IF(Z7>0,(Q7*Unit_Data!$D$26+S7*Unit_Data!$D$27)/Z7,0) -> 95.177632 | AE7: =SUMPRODUCT(X7:AC7,Product_Data!$C$4:$H$4) -> 13374.07 | AF7: =SUMPRODUCT(D7:G7,Crude_Data!$C$4:$F$4) -> 12094 | AG7: =J7*Unit_Data!$D$7+H7*Unit_Data!$D$10+I7*Unit_Data!$D$16+W7*Unit_Data!$D$24 -> 406.1 | AH7: =AE7-AF7-AG7 -> 873.97 | AI7: =IF(J7>0,AH7/J7,0) -> 5.8264667
A8: 4 | B8: 46299 | C8: Actual | D8: 39 | E8: 36 | F8: 39 | G8: 28 | H8: 21 | I8: 30 | J8: =SUM(D8:G8) -> 142 | K8: =SUMPRODUCT($D8:$G8,Crude_Data!$C$5:$F$5) -> 3.59 | L8: =SUMPRODUCT($D8:$G8,Crude_Data!$C$6:$F$6) -> 29.84 | M8: =SUMPRODUCT($D8:$G8,Crude_Data!$C$7:$F$7) -> 22.05 | N8: =SUMPRODUCT($D8:$G8,Crude_Data!$C$8:$F$8) -> 36.38 | O8: =SUMPRODUCT($D8:$G8,Crude_Data!$C$9:$F$9) -> 48.72 | P8: =IF(O8>0,SUMPRODUCT($D8:$G8,Crude_Data!$C$9:$F$9,Crude_Data!$C$12:$F$12)/O8,0) -> 1.4741687 | Q8: =H8*Unit_Data!$D$11 -> 17.64 | R8: =H8*Unit_Data!$D$12 -> 1.68 | S8: =I8*Unit_Data!$D$17 -> 15.6 | T8: =I8*Unit_Data!$D$18 -> 5.4 | U8: =I8*Unit_Data!$D$19 -> 5.4 | V8: =I8*Unit_Data!$D$20 -> 1.8 | W8: =N8+U8 -> 41.78 | X8: =K8+R8+T8 -> 10.67 | Y8: =L8-H8 -> 8.84 | Z8: =Q8+S8 -> 33.24 | AA8: =M8 -> 22.05 | AB8: =W8*Unit_Data!$D$25 -> 40.9444 | AC8: =O8-I8+V8 -> 20.52 | AD8: =IF(Z8>0,(Q8*Unit_Data!$D$26+S8*Unit_Data!$D$27)/Z8,0) -> 95.184116 | AE8: =SUMPRODUCT(X8:AC8,Product_Data!$C$4:$H$4) -> 12632.872 | AF8: =SUMPRODUCT(D8:G8,Crude_Data!$C$4:$F$4) -> 11448 | AG8: =J8*Unit_Data!$D$7+H8*Unit_Data!$D$10+I8*Unit_Data!$D$16+W8*Unit_Data!$D$24 -> 377.17 | AH8: =AE8-AF8-AG8 -> 807.702 | AI8: =IF(J8>0,AH8/J8,0) -> 5.6880423
A9: 5 | B9: 46300 | C9: Actual | D9: 35 | E9: 34 | F9: 37 | G9: 26 | H9: 19 | I9: 28 | J9: =SUM(D9:G9) -> 132 | K9: =SUMPRODUCT($D9:$G9,Crude_Data!$C$5:$F$5) -> 3.35 | L9: =SUMPRODUCT($D9:$G9,Crude_Data!$C$6:$F$6) -> 27.8 | M9: =SUMPRODUCT($D9:$G9,Crude_Data!$C$7:$F$7) -> 20.53 | N9: =SUMPRODUCT($D9:$G9,Crude_Data!$C$8:$F$8) -> 33.9 | O9: =SUMPRODUCT($D9:$G9,Crude_Data!$C$9:$F$9) -> 45.1 | P9: =IF(O9>0,SUMPRODUCT($D9:$G9,Crude_Data!$C$9:$F$9,Crude_Data!$C$12:$F$12)/O9,0) -> 1.4487029 | Q9: =H9*Unit_Data!$D$11 -> 15.96 | R9: =H9*Unit_Data!$D$12 -> 1.52 | S9: =I9*Unit_Data!$D$17 -> 14.56 | T9: =I9*Unit_Data!$D$18 -> 5.04 | U9: =I9*Unit_Data!$D$19 -> 5.04 | V9: =I9*Unit_Data!$D$20 -> 1.68 | W9: =N9+U9 -> 38.94 | X9: =K9+R9+T9 -> 9.91 | Y9: =L9-H9 -> 8.8 | Z9: =Q9+S9 -> 30.52 | AA9: =M9 -> 20.53 | AB9: =W9*Unit_Data!$D$25 -> 38.1612 | AC9: =O9-I9+V9 -> 18.78 | AD9: =IF(Z9>0,(Q9*Unit_Data!$D$26+S9*Unit_Data!$D$27)/Z9,0) -> 95.137615 | AE9: =SUMPRODUCT(X9:AC9,Product_Data!$C$4:$H$4) -> 11740.956 | AF9: =SUMPRODUCT(D9:G9,Crude_Data!$C$4:$F$4) -> 10650 | AG9: =J9*Unit_Data!$D$7+H9*Unit_Data!$D$10+I9*Unit_Data!$D$16+W9*Unit_Data!$D$24 -> 349.91 | AH9: =AE9-AF9-AG9 -> 741.046 | AI9: =IF(J9>0,AH9/J9,0) -> 5.6139848
A10: 6 | B10: 46301 | C10: Actual | D10: 37 | E10: 36 | F10: 38 | G10: 28 | H10: 20 | I10: 30 | J10: =SUM(D10:G10) -> 139 | K10: =SUMPRODUCT($D10:$G10,Crude_Data!$C$5:$F$5) -> 3.52 | L10: =SUMPRODUCT($D10:$G10,Crude_Data!$C$6:$F$6) -> 29.26 | M10: =SUMPRODUCT($D10:$G10,Crude_Data!$C$7:$F$7) -> 21.6 | N10: =SUMPRODUCT($D10:$G10,Crude_Data!$C$8:$F$8) -> 35.68 | O10: =SUMPRODUCT($D10:$G10,Crude_Data!$C$9:$F$9) -> 47.55 | P10: =IF(O10>0,SUMPRODUCT($D10:$G10,Crude_Data!$C$9:$F$9,Crude_Data!$C$12:$F$12)/O10,0) -> 1.4528076 | Q10: =H10*Unit_Data!$D$11 -> 16.8 | R10: =H10*Unit_Data!$D$12 -> 1.6 | S10: =I10*Unit_Data!$D$17 -> 15.6 | T10: =I10*Unit_Data!$D$18 -> 5.4 | U10: =I10*Unit_Data!$D$19 -> 5.4 | V10: =I10*Unit_Data!$D$20 -> 1.8 | W10: =N10+U10 -> 41.08 | X10: =K10+R10+T10 -> 10.52 | Y10: =L10-H10 -> 9.26 | Z10: =Q10+S10 -> 32.4 | AA10: =M10 -> 21.6 | AB10: =W10*Unit_Data!$D$25 -> 40.2584 | AC10: =O10-I10+V10 -> 19.35 | AD10: =IF(Z10>0,(Q10*Unit_Data!$D$26+S10*Unit_Data!$D$27)/Z10,0) -> 95.111111 | AE10: =SUMPRODUCT(X10:AC10,Product_Data!$C$4:$H$4) -> 12369.172 | AF10: =SUMPRODUCT(D10:G10,Crude_Data!$C$4:$F$4) -> 11212 | AG10: =J10*Unit_Data!$D$7+H10*Unit_Data!$D$10+I10*Unit_Data!$D$16+W10*Unit_Data!$D$24 -> 370.62 | AH10: =AE10-AF10-AG10 -> 786.552 | AI10: =IF(J10>0,AH10/J10,0) -> 5.6586475
A11: 7 | B11: 46302 | C11: Actual | D11: 39 | E11: 38 | F11: 40 | G11: 30 | H11: 22 | I11: 32 | J11: =SUM(D11:G11) -> 147 | K11: =SUMPRODUCT($D11:$G11,Crude_Data!$C$5:$F$5) -> 3.72 | L11: =SUMPRODUCT($D11:$G11,Crude_Data!$C$6:$F$6) -> 30.94 | M11: =SUMPRODUCT($D11:$G11,Crude_Data!$C$7:$F$7) -> 22.84 | N11: =SUMPRODUCT($D11:$G11,Crude_Data!$C$8:$F$8) -> 37.76 | O11: =SUMPRODUCT($D11:$G11,Crude_Data!$C$9:$F$9) -> 50.27 | P11: =IF(O11>0,SUMPRODUCT($D11:$G11,Crude_Data!$C$9:$F$9,Crude_Data!$C$12:$F$12)/O11,0) -> 1.4494927 | Q11: =H11*Unit_Data!$D$11 -> 18.48 | R11: =H11*Unit_Data!$D$12 -> 1.76 | S11: =I11*Unit_Data!$D$17 -> 16.64 | T11: =I11*Unit_Data!$D$18 -> 5.76 | U11: =I11*Unit_Data!$D$19 -> 5.76 | V11: =I11*Unit_Data!$D$20 -> 1.92 | W11: =N11+U11 -> 43.52 | X11: =K11+R11+T11 -> 11.24 | Y11: =L11-H11 -> 8.94 | Z11: =Q11+S11 -> 35.12 | AA11: =M11 -> 22.84 | AB11: =W11*Unit_Data!$D$25 -> 42.6496 | AC11: =O11-I11+V11 -> 20.19 | AD11: =IF(Z11>0,(Q11*Unit_Data!$D$26+S11*Unit_Data!$D$27)/Z11,0) -> 95.157175 | AE11: =SUMPRODUCT(X11:AC11,Product_Data!$C$4:$H$4) -> 13097.248 | AF11: =SUMPRODUCT(D11:G11,Crude_Data!$C$4:$F$4) -> 11858 | AG11: =J11*Unit_Data!$D$7+H11*Unit_Data!$D$10+I11*Unit_Data!$D$16+W11*Unit_Data!$D$24 -> 395.28 | AH11: =AE11-AF11-AG11 -> 843.968 | AI11: =IF(J11>0,AH11/J11,0) -> 5.7412789
A12: 8 | B12: 46303 | C12: Actual | D12: 40 | E12: 40 | F12: 40 | G12: 30 | H12: 22 | I12: 33 | J12: =SUM(D12:G12) -> 150 | K12: =SUMPRODUCT($D12:$G12,Crude_Data!$C$5:$F$5) -> 3.8 | L12: =SUMPRODUCT($D12:$G12,Crude_Data!$C$6:$F$6) -> 31.6 | M12: =SUMPRODUCT($D12:$G12,Crude_Data!$C$7:$F$7) -> 23.3 | N12: =SUMPRODUCT($D12:$G12,Crude_Data!$C$8:$F$8) -> 38.4 | O12: =SUMPRODUCT($D12:$G12,Crude_Data!$C$9:$F$9) -> 51.4 | P12: =IF(O12>0,SUMPRODUCT($D12:$G12,Crude_Data!$C$9:$F$9,Crude_Data!$C$12:$F$12)/O12,0) -> 1.4610895 | Q12: =H12*Unit_Data!$D$11 -> 18.48 | R12: =H12*Unit_Data!$D$12 -> 1.76 | S12: =I12*Unit_Data!$D$17 -> 17.16 | T12: =I12*Unit_Data!$D$18 -> 5.94 | U12: =I12*Unit_Data!$D$19 -> 5.94 | V12: =I12*Unit_Data!$D$20 -> 1.98 | W12: =N12+U12 -> 44.34 | X12: =K12+R12+T12 -> 11.5 | Y12: =L12-H12 -> 9.6 | Z12: =Q12+S12 -> 35.64 | AA12: =M12 -> 23.3 | AB12: =W12*Unit_Data!$D$25 -> 43.4532 | AC12: =O12-I12+V12 -> 20.38 | AD12: =IF(Z12>0,(Q12*Unit_Data!$D$26+S12*Unit_Data!$D$27)/Z12,0) -> 95.111111 | AE12: =SUMPRODUCT(X12:AC12,Product_Data!$C$4:$H$4) -> 13358.606 | AF12: =SUMPRODUCT(D12:G12,Crude_Data!$C$4:$F$4) -> 12095 | AG12: =J12*Unit_Data!$D$7+H12*Unit_Data!$D$10+I12*Unit_Data!$D$16+W12*Unit_Data!$D$24 -> 403.51 | AH12: =AE12-AF12-AG12 -> 860.096 | AI12: =IF(J12>0,AH12/J12,0) -> 5.7339733
A13: 9 | B13: 46304 | C13: Actual | D13: 40 | E13: 40 | F13: 41 | G13: 29 | H13: 23 | I13: 33 | J13: =SUM(D13:G13) -> 150 | K13: =SUMPRODUCT($D13:$G13,Crude_Data!$C$5:$F$5) -> 3.81 | L13: =SUMPRODUCT($D13:$G13,Crude_Data!$C$6:$F$6) -> 31.62 | M13: =SUMPRODUCT($D13:$G13,Crude_Data!$C$7:$F$7) -> 23.32 | N13: =SUMPRODUCT($D13:$G13,Crude_Data!$C$8:$F$8) -> 38.38 | O13: =SUMPRODUCT($D13:$G13,Crude_Data!$C$9:$F$9) -> 51.37 | P13: =IF(O13>0,SUMPRODUCT($D13:$G13,Crude_Data!$C$9:$F$9,Crude_Data!$C$12:$F$12)/O13,0) -> 1.4615632 | Q13: =H13*Unit_Data!$D$11 -> 19.32 | R13: =H13*Unit_Data!$D$12 -> 1.84 | S13: =I13*Unit_Data!$D$17 -> 17.16 | T13: =I13*Unit_Data!$D$18 -> 5.94 | U13: =I13*Unit_Data!$D$19 -> 5.94 | V13: =I13*Unit_Data!$D$20 -> 1.98 | W13: =N13+U13 -> 44.32 | X13: =K13+R13+T13 -> 11.59 | Y13: =L13-H13 -> 8.62 | Z13: =Q13+S13 -> 36.48 | AA13: =M13 -> 23.32 | AB13: =W13*Unit_Data!$D$25 -> 43.4336 | AC13: =O13-I13+V13 -> 20.35 | AD13: =IF(Z13>0,(Q13*Unit_Data!$D$26+S13*Unit_Data!$D$27)/Z13,0) -> 95.177632 | AE13: =SUMPRODUCT(X13:AC13,Product_Data!$C$4:$H$4) -> 13372.488 | AF13: =SUMPRODUCT(D13:G13,Crude_Data!$C$4:$F$4) -> 12096.5 | AG13: =J13*Unit_Data!$D$7+H13*Unit_Data!$D$10+I13*Unit_Data!$D$16+W13*Unit_Data!$D$24 -> 405.98 | AH13: =AE13-AF13-AG13 -> 870.008 | AI13: =IF(J13>0,AH13/J13,0) -> 5.8000533
A14: 10 | B14: 46305 | C14: Actual | D14: 40 | E14: 40 | F14: 40 | G14: 30 | H14: 22 | I14: 32 | J14: =SUM(D14:G14) -> 150 | K14: =SUMPRODUCT($D14:$G14,Crude_Data!$C$5:$F$5) -> 3.8 | L14: =SUMPRODUCT($D14:$G14,Crude_Data!$C$6:$F$6) -> 31.6 | M14: =SUMPRODUCT($D14:$G14,Crude_Data!$C$7:$F$7) -> 23.3 | N14: =SUMPRODUCT($D14:$G14,Crude_Data!$C$8:$F$8) -> 38.4 | O14: =SUMPRODUCT($D14:$G14,Crude_Data!$C$9:$F$9) -> 51.4 | P14: =IF(O14>0,SUMPRODUCT($D14:$G14,Crude_Data!$C$9:$F$9,Crude_Data!$C$12:$F$12)/O14,0) -> 1.4610895 | Q14: =H14*Unit_Data!$D$11 -> 18.48 | R14: =H14*Unit_Data!$D$12 -> 1.76 | S14: =I14*Unit_Data!$D$17 -> 16.64 | T14: =I14*Unit_Data!$D$18 -> 5.76 | U14: =I14*Unit_Data!$D$19 -> 5.76 | V14: =I14*Unit_Data!$D$20 -> 1.92 | W14: =N14+U14 -> 44.16 | X14: =K14+R14+T14 -> 11.32 | Y14: =L14-H14 -> 9.6 | Z14: =Q14+S14 -> 35.12 | AA14: =M14 -> 23.3 | AB14: =W14*Unit_Data!$D$25 -> 43.2768 | AC14: =O14-I14+V14 -> 21.32 | AD14: =IF(Z14>0,(Q14*Unit_Data!$D$26+S14*Unit_Data!$D$27)/Z14,0) -> 95.157175 | AE14: =SUMPRODUCT(X14:AC14,Product_Data!$C$4:$H$4) -> 13345.484 | AF14: =SUMPRODUCT(D14:G14,Crude_Data!$C$4:$F$4) -> 12095 | AG14: =J14*Unit_Data!$D$7+H14*Unit_Data!$D$10+I14*Unit_Data!$D$16+W14*Unit_Data!$D$24 -> 399.24 | AH14: =AE14-AF14-AG14 -> 851.244 | AI14: =IF(J14>0,AH14/J14,0) -> 5.67496
A15: 11 | B15: 46306 | C15: Actual | D15: 40 | E15: 40 | F15: 40 | G15: 30 | H15: 22 | I15: 32 | J15: =SUM(D15:G15) -> 150 | K15: =SUMPRODUCT($D15:$G15,Crude_Data!$C$5:$F$5) -> 3.8 | L15: =SUMPRODUCT($D15:$G15,Crude_Data!$C$6:$F$6) -> 31.6 | M15: =SUMPRODUCT($D15:$G15,Crude_Data!$C$7:$F$7) -> 23.3 | N15: =SUMPRODUCT($D15:$G15,Crude_Data!$C$8:$F$8) -> 38.4 | O15: =SUMPRODUCT($D15:$G15,Crude_Data!$C$9:$F$9) -> 51.4 | P15: =IF(O15>0,SUMPRODUCT($D15:$G15,Crude_Data!$C$9:$F$9,Crude_Data!$C$12:$F$12)/O15,0) -> 1.4610895 | Q15: =H15*Unit_Data!$D$11 -> 18.48 | R15: =H15*Unit_Data!$D$12 -> 1.76 | S15: =I15*Unit_Data!$D$17 -> 16.64 | T15: =I15*Unit_Data!$D$18 -> 5.76 | U15: =I15*Unit_Data!$D$19 -> 5.76 | V15: =I15*Unit_Data!$D$20 -> 1.92 | W15: =N15+U15 -> 44.16 | X15: =K15+R15+T15 -> 11.32 | Y15: =L15-H15 -> 9.6 | Z15: =Q15+S15 -> 35.12 | AA15: =M15 -> 23.3 | AB15: =W15*Unit_Data!$D$25 -> 43.2768 | AC15: =O15-I15+V15 -> 21.32 | AD15: =IF(Z15>0,(Q15*Unit_Data!$D$26+S15*Unit_Data!$D$27)/Z15,0) -> 95.157175 | AE15: =SUMPRODUCT(X15:AC15,Product_Data!$C$4:$H$4) -> 13345.484 | AF15: =SUMPRODUCT(D15:G15,Crude_Data!$C$4:$F$4) -> 12095 | AG15: =J15*Unit_Data!$D$7+H15*Unit_Data!$D$10+I15*Unit_Data!$D$16+W15*Unit_Data!$D$24 -> 399.24 | AH15: =AE15-AF15-AG15 -> 851.244 | AI15: =IF(J15>0,AH15/J15,0) -> 5.67496
A16: 12 | B16: 46307 | C16: Plan | D16: 40 | E16: 40 | F16: 40 | G16: 30 | H16: 22 | I16: 32 | J16: =SUM(D16:G16) -> 150 | K16: =SUMPRODUCT($D16:$G16,Crude_Data!$C$5:$F$5) -> 3.8 | L16: =SUMPRODUCT($D16:$G16,Crude_Data!$C$6:$F$6) -> 31.6 | M16: =SUMPRODUCT($D16:$G16,Crude_Data!$C$7:$F$7) -> 23.3 | N16: =SUMPRODUCT($D16:$G16,Crude_Data!$C$8:$F$8) -> 38.4 | O16: =SUMPRODUCT($D16:$G16,Crude_Data!$C$9:$F$9) -> 51.4 | P16: =IF(O16>0,SUMPRODUCT($D16:$G16,Crude_Data!$C$9:$F$9,Crude_Data!$C$12:$F$12)/O16,0) -> 1.4610895 | Q16: =H16*Unit_Data!$D$11 -> 18.48 | R16: =H16*Unit_Data!$D$12 -> 1.76 | S16: =I16*Unit_Data!$D$17 -> 16.64 | T16: =I16*Unit_Data!$D$18 -> 5.76 | U16: =I16*Unit_Data!$D$19 -> 5.76 | V16: =I16*Unit_Data!$D$20 -> 1.92 | W16: =N16+U16 -> 44.16 | X16: =K16+R16+T16 -> 11.32 | Y16: =L16-H16 -> 9.6 | Z16: =Q16+S16 -> 35.12 | AA16: =M16 -> 23.3 | AB16: =W16*Unit_Data!$D$25 -> 43.2768 | AC16: =O16-I16+V16 -> 21.32 | AD16: =IF(Z16>0,(Q16*Unit_Data!$D$26+S16*Unit_Data!$D$27)/Z16,0) -> 95.157175 | AE16: =SUMPRODUCT(X16:AC16,Product_Data!$C$4:$H$4) -> 13345.484 | AF16: =SUMPRODUCT(D16:G16,Crude_Data!$C$4:$F$4) -> 12095 | AG16: =J16*Unit_Data!$D$7+H16*Unit_Data!$D$10+I16*Unit_Data!$D$16+W16*Unit_Data!$D$24 -> 399.24 | AH16: =AE16-AF16-AG16 -> 851.244 | AI16: =IF(J16>0,AH16/J16,0) -> 5.67496
... A35: 31 | B35: 46326 | C35: Plan | D35: 40 | E35: 40 | F35: 40 | G35: 30 | H35: 22 | I35: 32 | J35: =SUM(D35:G35) -> 150 | K35: =SUMPRODUCT($D35:$G35,Crude_Data!$C$5:$F$5) -> 3.8 | L35: =SUMPRODUCT($D35:$G35,Crude_Data!$C$6:$F$6) -> 31.6 | M35: =SUMPRODUCT($D35:$G35,Crude_Data!$C$7:$F$7) -> 23.3 | N35: =SUMPRODUCT($D35:$G35,Crude_Data!$C$8:$F$8) -> 38.4 | O35: =SUMPRODUCT($D35:$G35,Crude_Data!$C$9:$F$9) -> 51.4 | P35: =IF(O35>0,SUMPRODUCT($D35:$G35,Crude_Data!$C$9:$F$9,Crude_Data!$C$12:$F$12)/O35,0) -> 1.4610895 | Q35: =H35*Unit_Data!$D$11 -> 18.48 | R35: =H35*Unit_Data!$D$12 -> 1.76 | S35: =I35*Unit_Data!$D$17 -> 16.64 | T35: =I35*Unit_Data!$D$18 -> 5.76 | U35: =I35*Unit_Data!$D$19 -> 5.76 | V35: =I35*Unit_Data!$D$20 -> 1.92 | W35: =N35+U35 -> 44.16 | X35: =K35+R35+T35 -> 11.32 | Y35: =L35-H35 -> 9.6 | Z35: =Q35+S35 -> 35.12 | AA35: =M35 -> 23.3 | AB35: =W35*Unit_Data!$D$25 -> 43.2768 | AC35: =O35-I35+V35 -> 21.32 | AD35: =IF(Z35>0,(Q35*Unit_Data!$D$26+S35*Unit_Data!$D$27)/Z35,0) -> 95.157175 | AE35: =SUMPRODUCT(X35:AC35,Product_Data!$C$4:$H$4) -> 13345.484 | AF35: =SUMPRODUCT(D35:G35,Crude_Data!$C$4:$F$4) -> 12095 | AG35: =J35*Unit_Data!$D$7+H35*Unit_Data!$D$10+I35*Unit_Data!$D$16+W35*Unit_Data!$D$24 -> 399.24 | AH35: =AE35-AF35-AG35 -> 851.244 | AI35: =IF(J35>0,AH35/J35,0) -> 5.67496
A36: Month | C36: Total | D36: =SUM(D5:D35) -> 1231 | E36: =SUM(E5:E35) -> 1222 | F36: =SUM(F5:F35) -> 1236 | G36: =SUM(G5:G35) -> 921 | H36: =SUM(H5:H35) -> 678 | I36: =SUM(I5:I35) -> 987 | J36: =SUM(J5:J35) -> 4610 | K36: =SUM(K5:K35) -> 116.78 | ... O36: =SUM(O5:O35) -> 1579.45 | P36: =AVERAGE(P5:P35) -> 1.4607668 | Q36: =SUM(Q5:Q35) -> 569.52 | R36: =SUM(R5:R35) -> 54.24 | S36: =SUM(S5:S35) -> 513.24 | T36: =SUM(T5:T35) -> 177.66 | U36: =SUM(U5:U35) -> 177.66 | V36: =SUM(V5:V35) -> 59.22 | W36: =SUM(W5:W35) -> 1358.22 | X36: =SUM(X5:X35) -> 348.68 | ... AC36: =SUM(AC5:AC35) -> 651.67 | AD36: =AVERAGE(AD5:AD35) -> 95.155761 | AE36: =SUM(AE5:AE35) -> 410237.03 | AF36: =SUM(AF5:AF35) -> 371733.5 | AG36: =SUM(AG5:AG35) -> 12290.33 | AH36: =SUM(AH5:AH35) -> 26213.198 | AI36: =IF(J36>0,AH36/J36,0) -> 5.6861601
A38: KPIs
A39: Month gross margin ($k) | G39: =AH36 -> 26213.198
A40: Actual-days margin ($k) – locked | G40: =SUMIF(C5:C35,"Actual",AH5:AH35) -> 9188.318
A41: Plan-days margin ($k) – OBJECTIVE | G41: =SUMIF(C5:C35,"Plan",AH5:AH35) -> 17024.88
A42: Total crude run (kbbl) | G42: =J36 -> 4610
A43: Constraint violations (from Constraint_Check) | G43: =Constraint_Check!X37 -> 0
A44: Plan status | G44: =IF(Constraint_Check!X37=0,"FEASIBLE","INFEASIBLE – see Constraint_Check") -> FEASIBLE

Sheet Tank_Balance
A1: Daily Tank Balance (kbbl) – long format, one row per tank per day
A2: Closing = Opening + Inflow − Outflow. Crude: inflow = receipts, outflow = CDU charge. Product: inflow = production, outflow = liftings.
A4: Tank ID | B4: Service | C4: Type | D4: Day | E4: Date | F4: Opening | G4: Inflow | H4: Outflow | I4: Closing | J4: Min heel | K4: Capacity | L4: Status | M4: Fill %
A5: TK-101 | B5: Arab Light | C5: Crude | D5: 1 | E5: =Daily_Plan!B5 -> 46296 | F5: =Tank_Master!$F$4 -> 700 | G5: =Crude_Receipts!C5 -> 0 | H5: =Daily_Plan!D5 -> 40 | I5: =F5+G5-H5 -> 660 | J5: =Tank_Master!$E$4 -> 150 | K5: =Tank_Master!$D$4 -> 1500 | L5: =IF(I5<J5-0.001,"BELOW MIN",IF(I5>K5+0.001,"ABOVE MAX","OK")) -> OK | M5: =IF(K5>0,I5/K5,0) -> 0.44
A6: TK-101 | B6: Arab Light | C6: Crude | D6: 2 | E6: =Daily_Plan!B6 -> 46297 | F6: =I5 -> 660 | G6: =Crude_Receipts!C6 -> 0 | H6: =Daily_Plan!D6 -> 40 | I6: =F6+G6-H6 -> 620 | J6: =Tank_Master!$E$4 -> 150 | K6: =Tank_Master!$D$4 -> 1500 | L6: =IF(I6<J6-0.001,"BELOW MIN",IF(I6>K6+0.001,"ABOVE MAX","OK")) -> OK | M6: =IF(K6>0,I6/K6,0) -> 0.41333333
A7: TK-101 | B7: Arab Light | C7: Crude | D7: 3 | E7: =Daily_Plan!B7 -> 46298 | F7: =I6 -> 620 | G7: =Crude_Receipts!C7 -> 0 | H7: =Daily_Plan!D7 -> 41 | I7: =F7+G7-H7 -> 579 | J7: =Tank_Master!$E$4 -> 150 | K7: =Tank_Master!$D$4 -> 1500 | L7: =IF(I7<J7-0.001,"BELOW MIN",IF(I7>K7+0.001,"ABOVE MAX","OK")) -> OK | M7: =IF(K7>0,I7/K7,0) -> 0.386
A8: TK-101 | B8: Arab Light | C8: Crude | D8: 4 | E8: =Daily_Plan!B8 -> 46299 | F8: =I7 -> 579 | G8: =Crude_Receipts!C8 -> 0 | H8: =Daily_Plan!D8 -> 39 | I8: =F8+G8-H8 -> 540 | J8: =Tank_Master!$E$4 -> 150 | K8: =Tank_Master!$D$4 -> 1500 | L8: =IF(I8<J8-0.001,"BELOW MIN",IF(I8>K8+0.001,"ABOVE MAX","OK")) -> OK | M8: =IF(K8>0,I8/K8,0) -> 0.36
A9: TK-101 | B9: Arab Light | C9: Crude | D9: 5 | E9: =Daily_Plan!B9 -> 46300 | F9: =I8 -> 540 | G9: =Crude_Receipts!C9 -> 0 | H9: =Daily_Plan!D9 -> 35 | I9: =F9+G9-H9 -> 505 | J9: =Tank_Master!$E$4 -> 150 | K9: =Tank_Master!$D$4 -> 1500 | L9: =IF(I9<J9-0.001,"BELOW MIN",IF(I9>K9+0.001,"ABOVE MAX","OK")) -> OK | M9: =IF(K9>0,I9/K9,0) -> 0.33666667
A10: TK-101 | B10: Arab Light | C10: Crude | D10: 6 | E10: =Daily_Plan!B10 -> 46301 | F10: =I9 -> 505 | G10: =Crude_Receipts!C10 -> 0 | H10: =Daily_Plan!D10 -> 37 | I10: =F10+G10-H10 -> 468 | J10: =Tank_Master!$E$4 -> 150 | K10: =Tank_Master!$D$4 -> 1500 | L10: =IF(I10<J10-0.001,"BELOW MIN",IF(I10>K10+0.001,"ABOVE MAX","OK")) -> OK | M10: =IF(K10>0,I10/K10,0) -> 0.312
A11: TK-101 | B11: Arab Light | C11: Crude | D11: 7 | E11: =Daily_Plan!B11 -> 46302 | F11: =I10 -> 468 | G11: =Crude_Receipts!C11 -> 0 | H11: =Daily_Plan!D11 -> 39 | I11: =F11+G11-H11 -> 429 | J11: =Tank_Master!$E$4 -> 150 | K11: =Tank_Master!$D$4 -> 1500 | L11: =IF(I11<J11-0.001,"BELOW MIN",IF(I11>K11+0.001,"ABOVE MAX","OK")) -> OK | M11: =IF(K11>0,I11/K11,0) -> 0.286
A12: TK-101 | B12: Arab Light | C12: Crude | D12: 8 | E12: =Daily_Plan!B12 -> 46303 | F12: =I11 -> 429 | G12: =Crude_Receipts!C12 -> 600 | H12: =Daily_Plan!D12 -> 40 | I12: =F12+G12-H12 -> 989 | J12: =Tank_Master!$E$4 -> 150 | K12: =Tank_Master!$D$4 -> 1500 | L12: =IF(I12<J12-0.001,"BELOW MIN",IF(I12>K12+0.001,"ABOVE MAX","OK")) -> OK | M12: =IF(K12>0,I12/K12,0) -> 0.65933333
A13: TK-101 | B13: Arab Light | C13: Crude | D13: 9 | E13: =Daily_Plan!B13 -> 46304 | F13: =I12 -> 989 | G13: =Crude_Receipts!C13 -> 0 | H13: =Daily_Plan!D13 -> 40 | I13: =F13+G13-H13 -> 949 | J13: =Tank_Master!$E$4 -> 150 | K13: =Tank_Master!$D$4 -> 1500 | L13: =IF(I13<J13-0.001,"BELOW MIN",IF(I13>K13+0.001,"ABOVE MAX","OK")) -> OK | M13: =IF(K13>0,I13/K13,0) -> 0.63266667
A14: TK-101 | B14: Arab Light | C14: Crude | D14: 10 | E14: =Daily_Plan!B14 -> 46305 | F14: =I13 -> 949 | G14: =Crude_Receipts!C14 -> 0 | H14: =Daily_Plan!D14 -> 40 | I14: =F14+G14-H14 -> 909 | J14: =Tank_Master!$E$4 -> 150 | K14: =Tank_Master!$D$4 -> 1500 | L14: =IF(I14<J14-0.001,"BELOW MIN",IF(I14>K14+0.001,"ABOVE MAX","OK")) -> OK | M14: =IF(K14>0,I14/K14,0) -> 0.606
A15: TK-101 | B15: Arab Light | C15: Crude | D15: 11 | E15: =Daily_Plan!B15 -> 46306 | F15: =I14 -> 909 | G15: =Crude_Receipts!C15 -> 0 | H15: =Daily_Plan!D15 -> 40 | I15: =F15+G15-H15 -> 869 | J15: =Tank_Master!$E$4 -> 150 | K15: =Tank_Master!$D$4 -> 1500 | L15: =IF(I15<J15-0.001,"BELOW MIN",IF(I15>K15+0.001,"ABOVE MAX","OK")) -> OK | M15: =IF(K15>0,I15/K15,0) -> 0.57933333
A16: TK-101 | B16: Arab Light | C16: Crude | D16: 12 | E16: =Daily_Plan!B16 -> 46307 | F16: =I15 -> 869 | G16: =Crude_Receipts!C16 -> 0 | H16: =Daily_Plan!D16 -> 40 | I16: =F16+G16-H16 -> 829 | J16: =Tank_Master!$E$4 -> 150 | K16: =Tank_Master!$D$4 -> 1500 | L16: =IF(I16<J16-0.001,"BELOW MIN",IF(I16>K16+0.001,"ABOVE MAX","OK")) -> OK | M16: =IF(K16>0,I16/K16,0) -> 0.55266667
A17: TK-101 | B17: Arab Light | C17: Crude | D17: 13 | E17: =Daily_Plan!B17 -> 46308 | F17: =I16 -> 829 | G17: =Crude_Receipts!C17 -> 0 | H17: =Daily_Plan!D17 -> 40 | I17: =F17+G17-H17 -> 789 | J17: =Tank_Master!$E$4 -> 150 | K17: =Tank_Master!$D$4 -> 1500 | L17: =IF(I17<J17-0.001,"BELOW MIN",IF(I17>K17+0.001,"ABOVE MAX","OK")) -> OK | M17: =IF(K17>0,I17/K17,0) -> 0.526
... A35: TK-101 | B35: Arab Light | C35: Crude | D35: 31 | E35: =Daily_Plan!B35 -> 46326 | F35: =I34 -> 609 | G35: =Crude_Receipts!C35 -> 0 | H35: =Daily_Plan!D35 -> 40 | I35: =F35+G35-H35 -> 569 | J35: =Tank_Master!$E$4 -> 150 | K35: =Tank_Master!$D$4 -> 1500 | L35: =IF(I35<J35-0.001,"BELOW MIN",IF(I35>K35+0.001,"ABOVE MAX","OK")) -> OK | M35: =IF(K35>0,I35/K35,0) -> 0.37933333
A36: TK-102 | B36: Murban | C36: Crude | D36: 1 | E36: =Daily_Plan!B5 -> 46296 | F36: =Tank_Master!$F$5 -> 500 | G36: =Crude_Receipts!D5 -> 0 | H36: =Daily_Plan!E5 -> 40 | I36: =F36+G36-H36 -> 460 | J36: =Tank_Master!$E$5 -> 100 | K36: =Tank_Master!$D$5 -> 1000 | L36: =IF(I36<J36-0.001,"BELOW MIN",IF(I36>K36+0.001,"ABOVE MAX","OK")) -> OK | M36: =IF(K36>0,I36/K36,0) -> 0.46
A37: TK-102 | B37: Murban | C37: Crude | D37: 2 | E37: =Daily_Plan!B6 -> 46297 | F37: =I36 -> 460 | G37: =Crude_Receipts!D6 -> 0 | H37: =Daily_Plan!E6 -> 40 | I37: =F37+G37-H37 -> 420 | J37: =Tank_Master!$E$5 -> 100 | K37: =Tank_Master!$D$5 -> 1000 | L37: =IF(I37<J37-0.001,"BELOW MIN",IF(I37>K37+0.001,"ABOVE MAX","OK")) -> OK | M37: =IF(K37>0,I37/K37,0) -> 0.42
A38: TK-102 | B38: Murban | C38: Crude | D38: 3 | E38: =Daily_Plan!B7 -> 46298 | F38: =I37 -> 420 | G38: =Crude_Receipts!D7 -> 0 | H38: =Daily_Plan!E7 -> 38 | I38: =F38+G38-H38 -> 382 | J38: =Tank_Master!$E$5 -> 100 | K38: =Tank_Master!$D$5 -> 1000 | L38: =IF(I38<J38-0.001,"BELOW MIN",IF(I38>K38+0.001,"ABOVE MAX","OK")) -> OK | M38: =IF(K38>0,I38/K38,0) -> 0.382
A39: TK-102 | B39: Murban | C39: Crude | D39: 4 | E39: =Daily_Plan!B8 -> 46299 | F39: =I38 -> 382 | G39: =Crude_Receipts!D8 -> 0 | H39: =Daily_Plan!E8 -> 36 | I39: =F39+G39-H39 -> 346 | J39: =Tank_Master!$E$5 -> 100 | K39: =Tank_Master!$D$5 -> 1000 | L39: =IF(I39<J39-0.001,"BELOW MIN",IF(I39>K39+0.001,"ABOVE MAX","OK")) -> OK | M39: =IF(K39>0,I39/K39,0) -> 0.346
A40: TK-102 | B40: Murban | C40: Crude | D40: 5 | E40: =Daily_Plan!B9 -> 46300 | F40: =I39 -> 346 | G40: =Crude_Receipts!D9 -> 500 | H40: =Daily_Plan!E9 -> 34 | I40: =F40+G40-H40 -> 812 | J40: =Tank_Master!$E$5 -> 100 | K40: =Tank_Master!$D$5 -> 1000 | L40: =IF(I40<J40-0.001,"BELOW MIN",IF(I40>K40+0.001,"ABOVE MAX","OK")) -> OK | M40: =IF(K40>0,I40/K40,0) -> 0.812
A41: TK-102 | B41: Murban | C41: Crude | D41: 6 | E41: =Daily_Plan!B10 -> 46301 | F41: =I40 -> 812 | G41: =Crude_Receipts!D10 -> 0 | H41: =Daily_Plan!E10 -> 36 | I41: =F41+G41-H41 -> 776 | J41: =Tank_Master!$E$5 -> 100 | K41: =Tank_Master!$D$5 -> 1000 | L41: =IF(I41<J41-0.001,"BELOW MIN",IF(I41>K41+0.001,"ABOVE MAX","OK")) -> OK | M41: =IF(K41>0,I41/K41,0) -> 0.776
A42: TK-102 | B42: Murban | C42: Crude | D42: 7 | E42: =Daily_Plan!B11 -> 46302 | F42: =I41 -> 776 | G42: =Crude_Receipts!D11 -> 0 | H42: =Daily_Plan!E11 -> 38 | I42: =F42+G42-H42 -> 738 | J42: =Tank_Master!$E$5 -> 100 | K42: =Tank_Master!$D$5 -> 1000 | L42: =IF(I42<J42-0.001,"BELOW MIN",IF(I42>K42+0.001,"ABOVE MAX","OK")) -> OK | M42: =IF(K42>0,I42/K42,0) -> 0.738
A43: TK-102 | B43: Murban | C43: Crude | D43: 8 | E43: =Daily_Plan!B12 -> 46303 | F43: =I42 -> 738 | G43: =Crude_Receipts!D12 -> 0 | H43: =Daily_Plan!E12 -> 40 | I43: =F43+G43-H43 -> 698 | J43: =Tank_Master!$E$5 -> 100 | K43: =Tank_Master!$D$5 -> 1000 | L43: =IF(I43<J43-0.001,"BELOW MIN",IF(I43>K43+0.001,"ABOVE MAX","OK")) -> OK | M43: =IF(K43>0,I43/K43,0) -> 0.698
A44: TK-102 | B44: Murban | C44: Crude | D44: 9 | E44: =Daily_Plan!B13 -> 46304 | F44: =I43 -> 698 | G44: =Crude_Receipts!D13 -> 0 | H44: =Daily_Plan!E13 -> 40 | I44: =F44+G44-H44 -> 658 | J44: =Tank_Master!$E$5 -> 100 | K44: =Tank_Master!$D$5 -> 1000 | L44: =IF(I44<J44-0.001,"BELOW MIN",IF(I44>K44+0.001,"ABOVE MAX","OK")) -> OK | M44: =IF(K44>0,I44/K44,0) -> 0.658
A45: TK-102 | B45: Murban | C45: Crude | D45: 10 | E45: =Daily_Plan!B14 -> 46305 | F45: =I44 -> 658 | G45: =Crude_Receipts!D14 -> 0 | H45: =Daily_Plan!E14 -> 40 | I45: =F45+G45-H45 -> 618 | J45: =Tank_Master!$E$5 -> 100 | K45: =Tank_Master!$D$5 -> 1000 | L45: =IF(I45<J45-0.001,"BELOW MIN",IF(I45>K45+0.001,"ABOVE MAX","OK")) -> OK | M45: =IF(K45>0,I45/K45,0) -> 0.618
A46: TK-102 | B46: Murban | C46: Crude | D46: 11 | E46: =Daily_Plan!B15 -> 46306 | F46: =I45 -> 618 | G46: =Crude_Receipts!D15 -> 0 | H46: =Daily_Plan!E15 -> 40 | I46: =F46+G46-H46 -> 578 | J46: =Tank_Master!$E$5 -> 100 | K46: =Tank_Master!$D$5 -> 1000 | L46: =IF(I46<J46-0.001,"BELOW MIN",IF(I46>K46+0.001,"ABOVE MAX","OK")) -> OK | M46: =IF(K46>0,I46/K46,0) -> 0.578
A47: TK-102 | B47: Murban | C47: Crude | D47: 12 | E47: =Daily_Plan!B16 -> 46307 | F47: =I46 -> 578 | G47: =Crude_Receipts!D16 -> 0 | H47: =Daily_Plan!E16 -> 40 | I47: =F47+G47-H47 -> 538 | J47: =Tank_Master!$E$5 -> 100 | K47: =Tank_Master!$D$5 -> 1000 | L47: =IF(I47<J47-0.001,"BELOW MIN",IF(I47>K47+0.001,"ABOVE MAX","OK")) -> OK | M47: =IF(K47>0,I47/K47,0) -> 0.538
A48: TK-102 | B48: Murban | C48: Crude | D48: 13 | E48: =Daily_Plan!B17 -> 46308 | F48: =I47 -> 538 | G48: =Crude_Receipts!D17 -> 0 | H48: =Daily_Plan!E17 -> 40 | I48: =F48+G48-H48 -> 498 | J48: =Tank_Master!$E$5 -> 100 | K48: =Tank_Master!$D$5 -> 1000 | L48: =IF(I48<J48-0.001,"BELOW MIN",IF(I48>K48+0.001,"ABOVE MAX","OK")) -> OK | M48: =IF(K48>0,I48/K48,0) -> 0.498
... A66: TK-102 | B66: Murban | C66: Crude | D66: 31 | E66: =Daily_Plan!B35 -> 46326 | F66: =I65 -> 318 | G66: =Crude_Receipts!D35 -> 0 | H66: =Daily_Plan!E35 -> 40 | I66: =F66+G66-H66 -> 278 | J66: =Tank_Master!$E$5 -> 100 | K66: =Tank_Master!$D$5 -> 1000 | L66: =IF(I66<J66-0.001,"BELOW MIN",IF(I66>K66+0.001,"ABOVE MAX","OK")) -> OK | M66: =IF(K66>0,I66/K66,0) -> 0.278
A67: TK-103 | B67: Tapis | C67: Crude | D67: 1 | E67: =Daily_Plan!B5 -> 46296 | F67: =Tank_Master!$F$6 -> 450 | G67: =Crude_Receipts!E5 -> 0 | H67: =Daily_Plan!F5 -> 40 | I67: =F67+G67-H67 -> 410 | J67: =Tank_Master!$E$6 -> 90 | K67: =Tank_Master!$D$6 -> 900 | L67: =IF(I67<J67-0.001,"BELOW MIN",IF(I67>K67+0.001,"ABOVE MAX","OK")) -> OK | M67: =IF(K67>0,I67/K67,0) -> 0.45555556
A68: TK-103 | B68: Tapis | C68: Crude | D68: 2 | E68: =Daily_Plan!B6 -> 46297 | F68: =I67 -> 410 | G68: =Crude_Receipts!E6 -> 0 | H68: =Daily_Plan!F6 -> 40 | I68: =F68+G68-H68 -> 370 | J68: =Tank_Master!$E$6 -> 90 | K68: =Tank_Master!$D$6 -> 900 | L68: =IF(I68<J68-0.001,"BELOW MIN",IF(I68>K68+0.001,"ABOVE MAX","OK")) -> OK | M68: =IF(K68>0,I68/K68,0) -> 0.41111111
A69: TK-103 | B69: Tapis | C69: Crude | D69: 3 | E69: =Daily_Plan!B7 -> 46298 | F69: =I68 -> 370 | G69: =Crude_Receipts!E7 -> 0 | H69: =Daily_Plan!F7 -> 41 | I69: =F69+G69-H69 -> 329 | J69: =Tank_Master!$E$6 -> 90 | K69: =Tank_Master!$D$6 -> 900 | L69: =IF(I69<J69-0.001,"BELOW MIN",IF(I69>K69+0.001,"ABOVE MAX","OK")) -> OK | M69: =IF(K69>0,I69/K69,0) -> 0.36555556
A70: TK-103 | B70: Tapis | C70: Crude | D70: 4 | E70: =Daily_Plan!B8 -> 46299 | F70: =I69 -> 329 | G70: =Crude_Receipts!E8 -> 0 | H70: =Daily_Plan!F8 -> 39 | I70: =F70+G70-H70 -> 290 | J70: =Tank_Master!$E$6 -> 90 | K70: =Tank_Master!$D$6 -> 900 | L70: =IF(I70<J70-0.001,"BELOW MIN",IF(I70>K70+0.001,"ABOVE MAX","OK")) -> OK | M70: =IF(K70>0,I70/K70,0) -> 0.32222222
A71: TK-103 | B71: Tapis | C71: Crude | D71: 5 | E71: =Daily_Plan!B9 -> 46300 | F71: =I70 -> 290 | G71: =Crude_Receipts!E9 -> 0 | H71: =Daily_Plan!F9 -> 37 | I71: =F71+G71-H71 -> 253 | J71: =Tank_Master!$E$6 -> 90 | K71: =Tank_Master!$D$6 -> 900 | L71: =IF(I71<J71-0.001,"BELOW MIN",IF(I71>K71+0.001,"ABOVE MAX","OK")) -> OK | M71: =IF(K71>0,I71/K71,0) -> 0.28111111
A72: TK-103 | B72: Tapis | C72: Crude | D72: 6 | E72: =Daily_Plan!B10 -> 46301 | F72: =I71 -> 253 | G72: =Crude_Receipts!E10 -> 400 | H72: =Daily_Plan!F10 -> 38 | I72: =F72+G72-H72 -> 615 | J72: =Tank_Master!$E$6 -> 90 | K72: =Tank_Master!$D$6 -> 900 | L72: =IF(I72<J72-0.001,"BELOW MIN",IF(I72>K72+0.001,"ABOVE MAX","OK")) -> OK | M72: =IF(K72>0,I72/K72,0) -> 0.68333333
A73: TK-103 | B73: Tapis | C73: Crude | D73: 7 | E73: =Daily_Plan!B11 -> 46302 | F73: =I72 -> 615 | G73: =Crude_Receipts!E11 -> 0 | H73: =Daily_Plan!F11 -> 40 | I73: =F73+G73-H73 -> 575 | J73: =Tank_Master!$E$6 -> 90 | K73: =Tank_Master!$D$6 -> 900 | L73: =IF(I73<J73-0.001,"BELOW MIN",IF(I73>K73+0.001,"ABOVE MAX","OK")) -> OK | M73: =IF(K73>0,I73/K73,0) -> 0.63888889
A74: TK-103 | B74: Tapis | C74: Crude | D74: 8 | E74: =Daily_Plan!B12 -> 46303 | F74: =I73 -> 575 | G74: =Crude_Receipts!E12 -> 0 | H74: =Daily_Plan!F12 -> 40 | I74: =F74+G74-H74 -> 535 | J74: =Tank_Master!$E$6 -> 90 | K74: =Tank_Master!$D$6 -> 900 | L74: =IF(I74<J74-0.001,"BELOW MIN",IF(I74>K74+0.001,"ABOVE MAX","OK")) -> OK | M74: =IF(K74>0,I74/K74,0) -> 0.59444444
A75: TK-103 | B75: Tapis | C75: Crude | D75: 9 | E75: =Daily_Plan!B13 -> 46304 | F75: =I74 -> 535 | G75: =Crude_Receipts!E13 -> 0 | H75: =Daily_Plan!F13 -> 41 | I75: =F75+G75-H75 -> 494 | J75: =Tank_Master!$E$6 -> 90 | K75: =Tank_Master!$D$6 -> 900 | L75: =IF(I75<J75-0.001,"BELOW MIN",IF(I75>K75+0.001,"ABOVE MAX","OK")) -> OK | M75: =IF(K75>0,I75/K75,0) -> 0.54888889
...

Sheet Tank_Summary
A1: Tank Inventory Overview – closing inventory (kbbl) and fill %
A2: Wide view of Tank_Balance for quick visual checks. All values are links.
C3: Closing inventory (kbbl) | N3: Fill % of working capacity
A4: Day | B4: Date | C4: TK-101 Arab Light | D4: TK-102 Murban | E4: TK-103 Tapis | F4: TK-104 Kimanis | G4: TK-201 LPG | H4: TK-301 Naphtha | I4: TK-401 Gasoline 95 | J4: TK-501 Jet A-1 | K4: TK-601 Diesel B10 | L4: TK-701 Fuel Oil | N4: TK-101 Arab Light | O4: TK-102 Murban | P4: TK-103 Tapis | Q4: TK-104 Kimanis | R4: TK-201 LPG | S4: TK-301 Naphtha | T4: TK-401 Gasoline 95 | U4: TK-501 Jet A-1 | V4: TK-601 Diesel B10 | W4: TK-701 Fuel Oil
A5: 1 | B5: =Daily_Plan!B5 -> 46296 | C5: =Tank_Balance!I5 -> 660 | D5: =Tank_Balance!I36 -> 460 | E5: =Tank_Balance!I67 -> 410 | F5: =Tank_Balance!I98 -> 350 | G5: =Tank_Balance!I129 -> 32.32 | H5: =Tank_Balance!I160 -> 119.6 | I5: =Tank_Balance!I191 -> 185.12 | J5: =Tank_Balance!I222 -> 145.3 | K5: =Tank_Balance!I253 -> 238.2768 | L5: =Tank_Balance!I284 -> 201.32 | N5: =Tank_Balance!M5 -> 0.44 | O5: =Tank_Balance!M36 -> 0.46 | P5: =Tank_Balance!M67 -> 0.45555556 | Q5: =Tank_Balance!M98 -> 0.4375 | R5: =Tank_Balance!M129 -> 0.53866667 | S5: =Tank_Balance!M160 -> 0.4784 | T5: =Tank_Balance!M191 -> 0.4628 | U5: =Tank_Balance!M222 -> 0.48433333 | V5: =Tank_Balance!M253 -> 0.4765536 | W5: =Tank_Balance!M284 -> 0.5033
A6: 2 | B6: =Daily_Plan!B6 -> 46297 | C6: =Tank_Balance!I6 -> 620 | D6: =Tank_Balance!I37 -> 420 | E6: =Tank_Balance!I68 -> 370 | F6: =Tank_Balance!I99 -> 320 | G6: =Tank_Balance!I130 -> 34.64 | H6: =Tank_Balance!I161 -> 129.2 | I6: =Tank_Balance!I192 -> 190.24 | J6: =Tank_Balance!I223 -> 150.6 | K6: =Tank_Balance!I254 -> 246.5536 | L6: =Tank_Balance!I285 -> 222.64 | N6: =Tank_Balance!M6 -> 0.41333333 | O6: =Tank_Balance!M37 -> 0.42 | P6: =Tank_Balance!M68 -> 0.41111111 | Q6: =Tank_Balance!M99 -> 0.4 | R6: =Tank_Balance!M130 -> 0.57733333 | S6: =Tank_Balance!M161 -> 0.5168 | T6: =Tank_Balance!M192 -> 0.4756 | U6: =Tank_Balance!M223 -> 0.502 | V6: =Tank_Balance!M254 -> 0.4931072 | W6: =Tank_Balance!M285 -> 0.5566
A7: 3 | B7: =Daily_Plan!B7 -> 46298 | C7: =Tank_Balance!I7 -> 579 | D7: =Tank_Balance!I38 -> 382 | E7: =Tank_Balance!I69 -> 329 | F7: =Tank_Balance!I100 -> 290 | G7: =Tank_Balance!I131 -> 37.21 | H7: =Tank_Balance!I162 -> 137.72 | I7: =Tank_Balance!I193 -> 196.72 | J7: =Tank_Balance!I224 -> 155.89 | K7: =Tank_Balance!I255 -> 255.0656 | L7: =Tank_Balance!I286 -> 243.06 | N7: =Tank_Balance!M7 -> 0.386 | O7: =Tank_Balance!M38 -> 0.382 | P7: =Tank_Balance!M69 -> 0.36555556 | Q7: =Tank_Balance!M100 -> 0.3625 | R7: =Tank_Balance!M131 -> 0.62016667 | S7: =Tank_Balance!M162 -> 0.55088 | T7: =Tank_Balance!M193 -> 0.4918 | U7: =Tank_Balance!M224 -> 0.51963333 | V7: =Tank_Balance!M255 -> 0.5101312 | W7: =Tank_Balance!M286 -> 0.60765
A8: 4 | B8: =Daily_Plan!B8 -> 46299 | C8: =Tank_Balance!I8 -> 540 | D8: =Tank_Balance!I39 -> 346 | E8: =Tank_Balance!I70 -> 290 | F8: =Tank_Balance!I101 -> 262 | G8: =Tank_Balance!I132 -> 38.88 | H8: =Tank_Balance!I163 -> 146.56 | I8: =Tank_Balance!I194 -> 199.96 | J8: =Tank_Balance!I225 -> 159.94 | K8: =Tank_Balance!I256 -> 261.01 | L8: =Tank_Balance!I287 -> 263.58 | N8: =Tank_Balance!M8 -> 0.36 | O8: =Tank_Balance!M39 -> 0.346 | P8: =Tank_Balance!M70 -> 0.32222222 | Q8: =Tank_Balance!M101 -> 0.3275 | R8: =Tank_Balance!M132 -> 0.648 | S8: =Tank_Balance!M163 -> 0.58624 | T8: =Tank_Balance!M194 -> 0.4999 | U8: =Tank_Balance!M225 -> 0.53313333 | V8: =Tank_Balance!M256 -> 0.52202 | W8: =Tank_Balance!M287 -> 0.65895
A9: 5 | B9: =Daily_Plan!B9 -> 46300 | C9: =Tank_Balance!I9 -> 505 | D9: =Tank_Balance!I40 -> 812 | E9: =Tank_Balance!I71 -> 253 | F9: =Tank_Balance!I102 -> 236 | G9: =Tank_Balance!I133 -> 39.79 | H9: =Tank_Balance!I164 -> 155.36 | I9: =Tank_Balance!I195 -> 200.48 | J9: =Tank_Balance!I226 -> 162.47 | K9: =Tank_Balance!I257 -> 264.1712 | L9: =Tank_Balance!I288 -> 282.36 | N9: =Tank_Balance!M9 -> 0.33666667 | O9: =Tank_Balance!M40 -> 0.812 | P9: =Tank_Balance!M71 -> 0.28111111 | Q9: =Tank_Balance!M102 -> 0.295 | R9: =Tank_Balance!M133 -> 0.66316667 | S9: =Tank_Balance!M164 -> 0.62144 | T9: =Tank_Balance!M195 -> 0.5012 | U9: =Tank_Balance!M226 -> 0.54156667 | V9: =Tank_Balance!M257 -> 0.5283424 | W9: =Tank_Balance!M288 -> 0.7059
A10: 6 | B10: =Daily_Plan!B10 -> 46301 | C10: =Tank_Balance!I10 -> 468 | D10: =Tank_Balance!I41 -> 776 | E10: =Tank_Balance!I72 -> 615 | F10: =Tank_Balance!I103 -> 208 | G10: =Tank_Balance!I134 -> 41.31 | H10: =Tank_Balance!I165 -> 164.62 | I10: =Tank_Balance!I196 -> 202.88 | J10: =Tank_Balance!I227 -> 166.07 | K10: =Tank_Balance!I258 -> 269.4296 | L10: =Tank_Balance!I289 -> 101.71 | N10: =Tank_Balance!M10 -> 0.312 | O10: =Tank_Balance!M41 -> 0.776 | P10: =Tank_Balance!M72 -> 0.68333333 | Q10: =Tank_Balance!M103 -> 0.26 | R10: =Tank_Balance!M134 -> 0.6885 | S10: =Tank_Balance!M165 -> 0.65848 | T10: =Tank_Balance!M196 -> 0.5072 | U10: =Tank_Balance!M227 -> 0.55356667 | V10: =Tank_Balance!M258 -> 0.5388592 | W10: =Tank_Balance!M289 -> 0.254275
A11: 7 | B11: =Daily_Plan!B11 -> 46302 | C11: =Tank_Balance!I11 -> 429 | D11: =Tank_Balance!I42 -> 738 | E11: =Tank_Balance!I73 -> 575 | F11: =Tank_Balance!I104 -> 178 | G11: =Tank_Balance!I135 -> 43.55 | H11: =Tank_Balance!I166 -> 173.56 | I11: =Tank_Balance!I197 -> 208 | J11: =Tank_Balance!I228 -> 85.91 | K11: =Tank_Balance!I259 -> 277.0792 | L11: =Tank_Balance!I290 -> 121.9 | N11: =Tank_Balance!M11 -> 0.286 | O11: =Tank_Balance!M42 -> 0.738 | P11: =Tank_Balance!M73 -> 0.63888889 | Q11: =Tank_Balance!M104 -> 0.2225 | R11: =Tank_Balance!M135 -> 0.72583333 | S11: =Tank_Balance!M166 -> 0.69424 | T11: =Tank_Balance!M197 -> 0.52 | U11: =Tank_Balance!M228 -> 0.28636667 | V11: =Tank_Balance!M259 -> 0.5541584 | W11: =Tank_Balance!M290 -> 0.30475
A12: 8 | B12: =Daily_Plan!B12 -> 46303 | C12: =Tank_Balance!I12 -> 989 | D12: =Tank_Balance!I43 -> 698 | E12: =Tank_Balance!I74 -> 535 | F12: =Tank_Balance!I105 -> 148 | G12: =Tank_Balance!I136 -> 46.05 | H12: =Tank_Balance!I167 -> 183.16 | I12: =Tank_Balance!I198 -> 213.64 | J12: =Tank_Balance!I229 -> 91.21 | K12: =Tank_Balance!I260 -> 285.5324 | L12: =Tank_Balance!I291 -> 142.28 | N12: =Tank_Balance!M12 -> 0.65933333 | O12: =Tank_Balance!M43 -> 0.698 | P12: =Tank_Balance!M74 -> 0.59444444 | Q12: =Tank_Balance!M105 -> 0.185 | R12: =Tank_Balance!M136 -> 0.7675 | S12: =Tank_Balance!M167 -> 0.73264 | T12: =Tank_Balance!M198 -> 0.5341 | U12: =Tank_Balance!M229 -> 0.30403333 | V12: =Tank_Balance!M260 -> 0.5710648 | W12: =Tank_Balance!M291 -> 0.3557
A13: 9 | B13: =Daily_Plan!B13 -> 46304 | C13: =Tank_Balance!I13 -> 949 | D13: =Tank_Balance!I44 -> 658 | E13: =Tank_Balance!I75 -> 494 | F13: =Tank_Balance!I106 -> 119 | G13: =Tank_Balance!I137 -> 48.64 | H13: =Tank_Balance!I168 -> 91.78 | I13: =Tank_Balance!I199 -> 220.12 | J13: =Tank_Balance!I230 -> 96.53 | K13: =Tank_Balance!I261 -> 293.966 | L13: =Tank_Balance!I292 -> 162.63 | N13: =Tank_Balance!M13 -> 0.63266667 | O13: =Tank_Balance!M44 -> 0.658 | P13: =Tank_Balance!M75 -> 0.54888889 | Q13: =Tank_Balance!M106 -> 0.14875 | R13: =Tank_Balance!M137 -> 0.81066667 | S13: =Tank_Balance!M168 -> 0.36712 | T13: =Tank_Balance!M199 -> 0.5503 | U13: =Tank_Balance!M230 -> 0.32176667 | V13: =Tank_Balance!M261 -> 0.587932 | W13: =Tank_Balance!M292 -> 0.406575
A14: 10 | B14: =Daily_Plan!B14 -> 46305 | C14: =Tank_Balance!I14 -> 909 | D14: =Tank_Balance!I45 -> 618 | E14: =Tank_Balance!I76 -> 454 | F14: =Tank_Balance!I107 -> 439 | G14: =Tank_Balance!I138 -> 20.96 | H14: =Tank_Balance!I169 -> 101.38 | I14: =Tank_Balance!I200 -> 225.24 | J14: =Tank_Balance!I231 -> 101.83 | K14: =Tank_Balance!I262 -> 302.2428 | L14: =Tank_Balance!I293 -> 183.95 | N14: =Tank_Balance!M14 -> 0.606 | O14: =Tank_Balance!M45 -> 0.618 | P14: =Tank_Balance!M76 -> 0.50444444 | Q14: =Tank_Balance!M107 -> 0.54875 | R14: =Tank_Balance!M138 -> 0.34933333 | S14: =Tank_Balance!M169 -> 0.40552 | T14: =Tank_Balance!M200 -> 0.5631 | U14: =Tank_Balance!M231 -> 0.33943333 | V14: =Tank_Balance!M262 -> 0.6044856 | W14: =Tank_Balance!M293 -> 0.459875
A15: 11 | B15: =Daily_Plan!B15 -> 46306 | C15: =Tank_Balance!I15 -> 869 | D15: =Tank_Balance!I46 -> 578 | E15: =Tank_Balance!I77 -> 414 | F15: =Tank_Balance!I108 -> 409 | G15: =Tank_Balance!I139 -> 23.28 | H15: =Tank_Balance!I170 -> 110.98 | I15: =Tank_Balance!I201 -> 230.36 | J15: =Tank_Balance!I232 -> 107.13 | K15: =Tank_Balance!I263 -> 170.5196 | L15: =Tank_Balance!I294 -> 205.27 | N15: =Tank_Balance!M15 -> 0.57933333 | O15: =Tank_Balance!M46 -> 0.578 | P15: =Tank_Balance!M77 -> 0.46 | Q15: =Tank_Balance!M108 -> 0.51125 | R15: =Tank_Balance!M139 -> 0.388 | S15: =Tank_Balance!M170 -> 0.44392 | T15: =Tank_Balance!M201 -> 0.5759 | U15: =Tank_Balance!M232 -> 0.3571 | V15: =Tank_Balance!M263 -> 0.3410392 | W15: =Tank_Balance!M294 -> 0.513175
A16: 12 | B16: =Daily_Plan!B16 -> 46307 | C16: =Tank_Balance!I16 -> 829 | D16: =Tank_Balance!I47 -> 538 | E16: =Tank_Balance!I78 -> 374 | F16: =Tank_Balance!I109 -> 379 | G16: =Tank_Balance!I140 -> 25.6 | H16: =Tank_Balance!I171 -> 120.58 | I16: =Tank_Balance!I202 -> 155.48 | J16: =Tank_Balance!I233 -> 112.43 | K16: =Tank_Balance!I264 -> 178.7964 | L16: =Tank_Balance!I295 -> 226.59 | N16: =Tank_Balance!M16 -> 0.55266667 | O16: =Tank_Balance!M47 -> 0.538 | P16: =Tank_Balance!M78 -> 0.41555556 | Q16: =Tank_Balance!M109 -> 0.47375 | R16: =Tank_Balance!M140 -> 0.42666667 | S16: =Tank_Balance!M171 -> 0.48232 | T16: =Tank_Balance!M202 -> 0.3887 | U16: =Tank_Balance!M233 -> 0.37476667 | V16: =Tank_Balance!M264 -> 0.3575928 | W16: =Tank_Balance!M295 -> 0.566475
... A35: 31 | B35: =Daily_Plan!B35 -> 46326 | C35: =Tank_Balance!I35 -> 569 | D35: =Tank_Balance!I66 -> 278 | E35: =Tank_Balance!I97 -> 414 | F35: =Tank_Balance!I128 -> 159 | G35: =Tank_Balance!I159 -> 39.68 | H35: =Tank_Balance!I190 -> 102.98 | I35: =Tank_Balance!I221 -> 172.76 | J35: =Tank_Balance!I252 -> 128.13 | K35: =Tank_Balance!I283 -> 196.0556 | L35: =Tank_Balance!I314 -> 231.67 | N35: =Tank_Balance!M35 -> 0.37933333 | O35: =Tank_Balance!M66 -> 0.278 | P35: =Tank_Balance!M97 -> 0.46 | Q35: =Tank_Balance!M128 -> 0.19875 | R35: =Tank_Balance!M159 -> 0.66133333 | S35: =Tank_Balance!M190 -> 0.41192 | T35: =Tank_Balance!M221 -> 0.4319 | U35: =Tank_Balance!M252 -> 0.4271 | V35: =Tank_Balance!M283 -> 0.3921112 | W35: =Tank_Balance!M314 -> 0.579175

Sheet Constraint_Check
A1: Constraint Check – does the current plan satisfy every plant constraint?
A2: Re-evaluates automatically when the optimizer writes new decision variables into Daily_Plan. VIOL = constraint breached.
A4: Day | B4: Date | C4: Status | D4: CDU rate | E4: C1 CDU cap | F4: Crude max | G4: C2 Crude rate | H4: CDU Δ vs prev day | I4: C3 Ramp | J4: Reformer feed | K4: C4 Ref cap | L4: C5 Naph avail | M4: RFCC feed | N4: C6 RFCC cap | O4: C7 Resid avail | P4: DHT feed | Q4: C8 DHT cap | R4: Gasoline RON | S4: C9 RON spec | T4: Residue S wt% | U4: C10 Sulfur | V4: Tank breaches | W4: C13 Tank limits | X4: Day result
A5: 1 | B5: =Daily_Plan!B5 -> 46296 | C5: =Daily_Plan!C5 -> Actual | D5: =Daily_Plan!J5 -> 150 | E5: =IF(AND(D5>=Unit_Data!$D$5-0.001,D5<=Unit_Data!$D$4+0.001),"OK","VIOL") -> OK | F5: =SUMPRODUCT(--(Daily_Plan!D5:G5>Crude_Data!$C$13:$F$13+0.001))+SUMPRODUCT(--(Daily_Plan!D5:G5<Crude_Data!$C$14:$F$14-0.001)) -> 0 | G5: =IF(F5=0,"OK","VIOL") -> OK | H5: n/a | I5: n/a | J5: =Daily_Plan!H5 -> 22 | K5: =IF(AND(J5>=Unit_Data!$D$9-0.001,J5<=Unit_Data!$D$8+0.001),"OK","VIOL") -> OK | L5: =IF(J5<=Daily_Plan!L5+0.001,"OK","VIOL") -> OK | M5: =Daily_Plan!I5 -> 32 | N5: =IF(AND(M5>=Unit_Data!$D$15-0.001,M5<=Unit_Data!$D$14+0.001),"OK","VIOL") -> OK | O5: =IF(M5<=Daily_Plan!O5+0.001,"OK","VIOL") -> OK | P5: =Daily_Plan!W5 -> 44.16 | Q5: =IF(AND(P5>=Unit_Data!$D$23-0.001,P5<=Unit_Data!$D$22+0.001),"OK","VIOL") -> OK | R5: =Daily_Plan!AD5 -> 95.157175 | S5: =IF(R5>=Unit_Data!$D$28-0.001,"OK","VIOL") -> OK | T5: =Daily_Plan!P5 -> 1.4610895 | U5: =IF(T5<=Unit_Data!$D$29+0.0001,"OK","VIOL") -> OK | V5: =COUNTIFS(Tank_Balance!$D$5:$D$314,A5,Tank_Balance!$L$5:$L$314,"<>OK") -> 0 | W5: =IF(V5=0,"OK","VIOL") -> OK | X5: =IF(COUNTIF(E5:W5,"VIOL")=0,"FEASIBLE","INFEASIBLE") -> FEASIBLE
A6: 2 | B6: =Daily_Plan!B6 -> 46297 | C6: =Daily_Plan!C6 -> Actual | D6: =Daily_Plan!J6 -> 150 | E6: =IF(AND(D6>=Unit_Data!$D$5-0.001,D6<=Unit_Data!$D$4+0.001),"OK","VIOL") -> OK | F6: =SUMPRODUCT(--(Daily_Plan!D6:G6>Crude_Data!$C$13:$F$13+0.001))+SUMPRODUCT(--(Daily_Plan!D6:G6<Crude_Data!$C$14:$F$14-0.001)) -> 0 | G6: =IF(F6=0,"OK","VIOL") -> OK | H6: =D6-D5 -> 0 | I6: =IF(ABS(H6)<=Unit_Data!$D$6+0.001,"OK","VIOL") -> OK | J6: =Daily_Plan!H6 -> 22 | K6: =IF(AND(J6>=Unit_Data!$D$9-0.001,J6<=Unit_Data!$D$8+0.001),"OK","VIOL") -> OK | L6: =IF(J6<=Daily_Plan!L6+0.001,"OK","VIOL") -> OK | M6: =Daily_Plan!I6 -> 32 | N6: =IF(AND(M6>=Unit_Data!$D$15-0.001,M6<=Unit_Data!$D$14+0.001),"OK","VIOL") -> OK | O6: =IF(M6<=Daily_Plan!O6+0.001,"OK","VIOL") -> OK | P6: =Daily_Plan!W6 -> 44.16 | Q6: =IF(AND(P6>=Unit_Data!$D$23-0.001,P6<=Unit_Data!$D$22+0.001),"OK","VIOL") -> OK | R6: =Daily_Plan!AD6 -> 95.157175 | S6: =IF(R6>=Unit_Data!$D$28-0.001,"OK","VIOL") -> OK | T6: =Daily_Plan!P6 -> 1.4610895 | U6: =IF(T6<=Unit_Data!$D$29+0.0001,"OK","VIOL") -> OK | V6: =COUNTIFS(Tank_Balance!$D$5:$D$314,A6,Tank_Balance!$L$5:$L$314,"<>OK") -> 0 | W6: =IF(V6=0,"OK","VIOL") -> OK | X6: =IF(COUNTIF(E6:W6,"VIOL")=0,"FEASIBLE","INFEASIBLE") -> FEASIBLE
A7: 3 | B7: =Daily_Plan!B7 -> 46298 | C7: =Daily_Plan!C7 -> Actual | D7: =Daily_Plan!J7 -> 150 | E7: =IF(AND(D7>=Unit_Data!$D$5-0.001,D7<=Unit_Data!$D$4+0.001),"OK","VIOL") -> OK | F7: =SUMPRODUCT(--(Daily_Plan!D7:G7>Crude_Data!$C$13:$F$13+0.001))+SUMPRODUCT(--(Daily_Plan!D7:G7<Crude_Data!$C$14:$F$14-0.001)) -> 0 | G7: =IF(F7=0,"OK","VIOL") -> OK | H7: =D7-D6 -> 0 | I7: =IF(ABS(H7)<=Unit_Data!$D$6+0.001,"OK","VIOL") -> OK | J7: =Daily_Plan!H7 -> 23 | K7: =IF(AND(J7>=Unit_Data!$D$9-0.001,J7<=Unit_Data!$D$8+0.001),"OK","VIOL") -> OK | L7: =IF(J7<=Daily_Plan!L7+0.001,"OK","VIOL") -> OK | M7: =Daily_Plan!I7 -> 33 | N7: =IF(AND(M7>=Unit_Data!$D$15-0.001,M7<=Unit_Data!$D$14+0.001),"OK","VIOL") -> OK | O7: =IF(M7<=Daily_Plan!O7+0.001,"OK","VIOL") -> OK | P7: =Daily_Plan!W7 -> 44.4 | Q7: =IF(AND(P7>=Unit_Data!$D$23-0.001,P7<=Unit_Data!$D$22+0.001),"OK","VIOL") -> OK | R7: =Daily_Plan!AD7 -> 95.177632 | S7: =IF(R7>=Unit_Data!$D$28-0.001,"OK","VIOL") -> OK | T7: =Daily_Plan!P7 -> 1.4697998 | U7: =IF(T7<=Unit_Data!$D$29+0.0001,"OK","VIOL") -> OK | V7: =COUNTIFS(Tank_Balance!$D$5:$D$314,A7,Tank_Balance!$L$5:$L$314,"<>OK") -> 0 | W7: =IF(V7=0,"OK","VIOL") -> OK | X7: =IF(COUNTIF(E7:W7,"VIOL")=0,"FEASIBLE","INFEASIBLE") -> FEASIBLE
A8: 4 | B8: =Daily_Plan!B8 -> 46299 | C8: =Daily_Plan!C8 -> Actual | D8: =Daily_Plan!J8 -> 142 | E8: =IF(AND(D8>=Unit_Data!$D$5-0.001,D8<=Unit_Data!$D$4+0.001),"OK","VIOL") -> OK | F8: =SUMPRODUCT(--(Daily_Plan!D8:G8>Crude_Data!$C$13:$F$13+0.001))+SUMPRODUCT(--(Daily_Plan!D8:G8<Crude_Data!$C$14:$F$14-0.001)) -> 0 | G8: =IF(F8=0,"OK","VIOL") -> OK | H8: =D8-D7 -> -8 | I8: =IF(ABS(H8)<=Unit_Data!$D$6+0.001,"OK","VIOL") -> OK | J8: =Daily_Plan!H8 -> 21 | K8: =IF(AND(J8>=Unit_Data!$D$9-0.001,J8<=Unit_Data!$D$8+0.001),"OK","VIOL") -> OK | L8: =IF(J8<=Daily_Plan!L8+0.001,"OK","VIOL") -> OK | M8: =Daily_Plan!I8 -> 30 | N8: =IF(AND(M8>=Unit_Data!$D$15-0.001,M8<=Unit_Data!$D$14+0.001),"OK","VIOL") -> OK | O8: =IF(M8<=Daily_Plan!O8+0.001,"OK","VIOL") -> OK | P8: =Daily_Plan!W8 -> 41.78 | Q8: =IF(AND(P8>=Unit_Data!$D$23-0.001,P8<=Unit_Data!$D$22+0.001),"OK","VIOL") -> OK | R8: =Daily_Plan!AD8 -> 95.184116 | S8: =IF(R8>=Unit_Data!$D$28-0.001,"OK","VIOL") -> OK | T8: =Daily_Plan!P8 -> 1.4741687 | U8: =IF(T8<=Unit_Data!$D$29+0.0001,"OK","VIOL") -> OK | V8: =COUNTIFS(Tank_Balance!$D$5:$D$314,A8,Tank_Balance!$L$5:$L$314,"<>OK") -> 0 | W8: =IF(V8=0,"OK","VIOL") -> OK | X8: =IF(COUNTIF(E8:W8,"VIOL")=0,"FEASIBLE","INFEASIBLE") -> FEASIBLE
A9: 5 | B9: =Daily_Plan!B9 -> 46300 | C9: =Daily_Plan!C9 -> Actual | D9: =Daily_Plan!J9 -> 132 | E9: =IF(AND(D9>=Unit_Data!$D$5-0.001,D9<=Unit_Data!$D$4+0.001),"OK","VIOL") -> OK | F9: =SUMPRODUCT(--(Daily_Plan!D9:G9>Crude_Data!$C$13:$F$13+0.001))+SUMPRODUCT(--(Daily_Plan!D9:G9<Crude_Data!$C$14:$F$14-0.001)) -> 0 | G9: =IF(F9=0,"OK","VIOL") -> OK | H9: =D9-D8 -> -10 | I9: =IF(ABS(H9)<=Unit_Data!$D$6+0.001,"OK","VIOL") -> OK | J9: =Daily_Plan!H9 -> 19 | K9: =IF(AND(J9>=Unit_Data!$D$9-0.001,J9<=Unit_Data!$D$8+0.001),"OK","VIOL") -> OK | L9: =IF(J9<=Daily_Plan!L9+0.001,"OK","VIOL") -> OK | M9: =Daily_Plan!I9 -> 28 | N9: =IF(AND(M9>=Unit_Data!$D$15-0.001,M9<=Unit_Data!$D$14+0.001),"OK","VIOL") -> OK | O9: =IF(M9<=Daily_Plan!O9+0.001,"OK","VIOL") -> OK | P9: =Daily_Plan!W9 -> 38.94 | Q9: =IF(AND(P9>=Unit_Data!$D$23-0.001,P9<=Unit_Data!$D$22+0.001),"OK","VIOL") -> OK | R9: =Daily_Plan!AD9 -> 95.137615 | S9: =IF(R9>=Unit_Data!$D$28-0.001,"OK","VIOL") -> OK | T9: =Daily_Plan!P9 -> 1.4487029 | U9: =IF(T9<=Unit_Data!$D$29+0.0001,"OK","VIOL") -> OK | V9: =COUNTIFS(Tank_Balance!$D$5:$D$314,A9,Tank_Balance!$L$5:$L$314,"<>OK") -> 0 | W9: =IF(V9=0,"OK","VIOL") -> OK | X9: =IF(COUNTIF(E9:W9,"VIOL")=0,"FEASIBLE","INFEASIBLE") -> FEASIBLE
A10: 6 | B10: =Daily_Plan!B10 -> 46301 | C10: =Daily_Plan!C10 -> Actual | D10: =Daily_Plan!J10 -> 139 | E10: =IF(AND(D10>=Unit_Data!$D$5-0.001,D10<=Unit_Data!$D$4+0.001),"OK","VIOL") -> OK | F10: =SUMPRODUCT(--(Daily_Plan!D10:G10>Crude_Data!$C$13:$F$13+0.001))+SUMPRODUCT(--(Daily_Plan!D10:G10<Crude_Data!$C$14:$F$14-0.001)) -> 0 | G10: =IF(F10=0,"OK","VIOL") -> OK | H10: =D10-D9 -> 7 | I10: =IF(ABS(H10)<=Unit_Data!$D$6+0.001,"OK","VIOL") -> OK | J10: =Daily_Plan!H10 -> 20 | K10: =IF(AND(J10>=Unit_Data!$D$9-0.001,J10<=Unit_Data!$D$8+0.001),"OK","VIOL") -> OK | L10: =IF(J10<=Daily_Plan!L10+0.001,"OK","VIOL") -> OK | M10: =Daily_Plan!I10 -> 30 | N10: =IF(AND(M10>=Unit_Data!$D$15-0.001,M10<=Unit_Data!$D$14+0.001),"OK","VIOL") -> OK | O10: =IF(M10<=Daily_Plan!O10+0.001,"OK","VIOL") -> OK | P10: =Daily_Plan!W10 -> 41.08 | Q10: =IF(AND(P10>=Unit_Data!$D$23-0.001,P10<=Unit_Data!$D$22+0.001),"OK","VIOL") -> OK | R10: =Daily_Plan!AD10 -> 95.111111 | S10: =IF(R10>=Unit_Data!$D$28-0.001,"OK","VIOL") -> OK | T10: =Daily_Plan!P10 -> 1.4528076 | U10: =IF(T10<=Unit_Data!$D$29+0.0001,"OK","VIOL") -> OK | V10: =COUNTIFS(Tank_Balance!$D$5:$D$314,A10,Tank_Balance!$L$5:$L$314,"<>OK") -> 0 | W10: =IF(V10=0,"OK","VIOL") -> OK | X10: =IF(COUNTIF(E10:W10,"VIOL")=0,"FEASIBLE","INFEASIBLE") -> FEASIBLE
A11: 7 | B11: =Daily_Plan!B11 -> 46302 | C11: =Daily_Plan!C11 -> Actual | D11: =Daily_Plan!J11 -> 147 | E11: =IF(AND(D11>=Unit_Data!$D$5-0.001,D11<=Unit_Data!$D$4+0.001),"OK","VIOL") -> OK | F11: =SUMPRODUCT(--(Daily_Plan!D11:G11>Crude_Data!$C$13:$F$13+0.001))+SUMPRODUCT(--(Daily_Plan!D11:G11<Crude_Data!$C$14:$F$14-0.001)) -> 0 | G11: =IF(F11=0,"OK","VIOL") -> OK | H11: =D11-D10 -> 8 | I11: =IF(ABS(H11)<=Unit_Data!$D$6+0.001,"OK","VIOL") -> OK | J11: =Daily_Plan!H11 -> 22 | K11: =IF(AND(J11>=Unit_Data!$D$9-0.001,J11<=Unit_Data!$D$8+0.001),"OK","VIOL") -> OK | L11: =IF(J11<=Daily_Plan!L11+0.001,"OK","VIOL") -> OK | M11: =Daily_Plan!I11 -> 32 | N11: =IF(AND(M11>=Unit_Data!$D$15-0.001,M11<=Unit_Data!$D$14+0.001),"OK","VIOL") -> OK | O11: =IF(M11<=Daily_Plan!O11+0.001,"OK","VIOL") -> OK | P11: =Daily_Plan!W11 -> 43.52 | Q11: =IF(AND(P11>=Unit_Data!$D$23-0.001,P11<=Unit_Data!$D$22+0.001),"OK","VIOL") -> OK | R11: =Daily_Plan!AD11 -> 95.157175 | S11: =IF(R11>=Unit_Data!$D$28-0.001,"OK","VIOL") -> OK | T11: =Daily_Plan!P11 -> 1.4494927 | U11: =IF(T11<=Unit_Data!$D$29+0.0001,"OK","VIOL") -> OK | V11: =COUNTIFS(Tank_Balance!$D$5:$D$314,A11,Tank_Balance!$L$5:$L$314,"<>OK") -> 0 | W11: =IF(V11=0,"OK","VIOL") -> OK | X11: =IF(COUNTIF(E11:W11,"VIOL")=0,"FEASIBLE","INFEASIBLE") -> FEASIBLE
A12: 8 | B12: =Daily_Plan!B12 -> 46303 | C12: =Daily_Plan!C12 -> Actual | D12: =Daily_Plan!J12 -> 150 | E12: =IF(AND(D12>=Unit_Data!$D$5-0.001,D12<=Unit_Data!$D$4+0.001),"OK","VIOL") -> OK | F12: =SUMPRODUCT(--(Daily_Plan!D12:G12>Crude_Data!$C$13:$F$13+0.001))+SUMPRODUCT(--(Daily_Plan!D12:G12<Crude_Data!$C$14:$F$14-0.001)) -> 0 | G12: =IF(F12=0,"OK","VIOL") -> OK | H12: =D12-D11 -> 3 | I12: =IF(ABS(H12)<=Unit_Data!$D$6+0.001,"OK","VIOL") -> OK | J12: =Daily_Plan!H12 -> 22 | K12: =IF(AND(J12>=Unit_Data!$D$9-0.001,J12<=Unit_Data!$D$8+0.001),"OK","VIOL") -> OK | L12: =IF(J12<=Daily_Plan!L12+0.001,"OK","VIOL") -> OK | M12: =Daily_Plan!I12 -> 33 | N12: =IF(AND(M12>=Unit_Data!$D$15-0.001,M12<=Unit_Data!$D$14+0.001),"OK","VIOL") -> OK | O12: =IF(M12<=Daily_Plan!O12+0.001,"OK","VIOL") -> OK | P12: =Daily_Plan!W12 -> 44.34 | Q12: =IF(AND(P12>=Unit_Data!$D$23-0.001,P12<=Unit_Data!$D$22+0.001),"OK","VIOL") -> OK | R12: =Daily_Plan!AD12 -> 95.111111 | S12: =IF(R12>=Unit_Data!$D$28-0.001,"OK","VIOL") -> OK | T12: =Daily_Plan!P12 -> 1.4610895 | U12: =IF(T12<=Unit_Data!$D$29+0.0001,"OK","VIOL") -> OK | V12: =COUNTIFS(Tank_Balance!$D$5:$D$314,A12,Tank_Balance!$L$5:$L$314,"<>OK") -> 0 | W12: =IF(V12=0,"OK","VIOL") -> OK | X12: =IF(COUNTIF(E12:W12,"VIOL")=0,"FEASIBLE","INFEASIBLE") -> FEASIBLE
A13: 9 | B13: =Daily_Plan!B13 -> 46304 | C13: =Daily_Plan!C13 -> Actual | D13: =Daily_Plan!J13 -> 150 | E13: =IF(AND(D13>=Unit_Data!$D$5-0.001,D13<=Unit_Data!$D$4+0.001),"OK","VIOL") -> OK | F13: =SUMPRODUCT(--(Daily_Plan!D13:G13>Crude_Data!$C$13:$F$13+0.001))+SUMPRODUCT(--(Daily_Plan!D13:G13<Crude_Data!$C$14:$F$14-0.001)) -> 0 | G13: =IF(F13=0,"OK","VIOL") -> OK | H13: =D13-D12 -> 0 | I13: =IF(ABS(H13)<=Unit_Data!$D$6+0.001,"OK","VIOL") -> OK | J13: =Daily_Plan!H13 -> 23 | K13: =IF(AND(J13>=Unit_Data!$D$9-0.001,J13<=Unit_Data!$D$8+0.001),"OK","VIOL") -> OK | L13: =IF(J13<=Daily_Plan!L13+0.001,"OK","VIOL") -> OK | M13: =Daily_Plan!I13 -> 33 | N13: =IF(AND(M13>=Unit_Data!$D$15-0.001,M13<=Unit_Data!$D$14+0.001),"OK","VIOL") -> OK | O13: =IF(M13<=Daily_Plan!O13+0.001,"OK","VIOL") -> OK | P13: =Daily_Plan!W13 -> 44.32 | Q13: =IF(AND(P13>=Unit_Data!$D$23-0.001,P13<=Unit_Data!$D$22+0.001),"OK","VIOL") -> OK | R13: =Daily_Plan!AD13 -> 95.177632 | S13: =IF(R13>=Unit_Data!$D$28-0.001,"OK","VIOL") -> OK | T13: =Daily_Plan!P13 -> 1.4615632 | U13: =IF(T13<=Unit_Data!$D$29+0.0001,"OK","VIOL") -> OK | V13: =COUNTIFS(Tank_Balance!$D$5:$D$314,A13,Tank_Balance!$L$5:$L$314,"<>OK") -> 0 | W13: =IF(V13=0,"OK","VIOL") -> OK | X13: =IF(COUNTIF(E13:W13,"VIOL")=0,"FEASIBLE","INFEASIBLE") -> FEASIBLE
